<?xml version="1.0" encoding="UTF-8"?>
<testsuite errors="1" failures="0" file="unittest/loader.py" name="unittest.loader._FailedTest-20200331104846" skipped="0" tests="1" time="0.011" timestamp="2020-03-31T10:48:46">
	<testcase classname="unittest.loader._FailedTest.data_steward.cdr_cleaner.cleaning_rules" file="/usr/local/Cellar/python/3.7.7/Frameworks/Python.framework/Versions/3.7/lib/python3.7/unittest/loader.py" line="33" name="ensure_date_datetime_test" time="0.011" timestamp="2020-03-31T10:48:46">
		<error message="Failed to import test module: data_steward.cdr_cleaner.cleaning_rules.ensure_date_datetime_test
Traceback (most recent call last):
  File &quot;/usr/local/Cellar/python/3.7.7/Frameworks/Python.framework/Versions/3.7/lib/python3.7/unittest/loader.py&quot;, line 436, in _find_test_path
    module = self._get_module_from_name(name)
  File &quot;/usr/local/Cellar/python/3.7.7/Frameworks/Python.framework/Versions/3.7/lib/python3.7/unittest/loader.py&quot;, line 377, in _get_module_from_name
    __import__(name)
  File &quot;/Users/danyelcampbell/workspace/curation/tests/unit_tests/data_steward/cdr_cleaner/cleaning_rules/ensure_date_datetime_test.py&quot;, line 3, in &lt;module&gt;
    from cdr_cleaner.cleaning_rules import ensure_date_datetime_consistency as eddc
  File &quot;/Users/danyelcampbell/workspace/curation/data_steward/cdr_cleaner/cleaning_rules/ensure_date_datetime_consistency.py&quot;, line 10, in &lt;module&gt;
    from cdr_cleaner.cleaning_rules import field_mapping
  File &quot;/Users/danyelcampbell/workspace/curation/data_steward/cdr_cleaner/cleaning_rules/field_mapping.py&quot;, line 5, in &lt;module&gt;
    import resources
  File &quot;/Users/danyelcampbell/workspace/curation/data_steward/resources.py&quot;, line 7, in &lt;module&gt;
    import cachetools
ModuleNotFoundError: No module named 'cachetools'
" type="ImportError">
<![CDATA[ImportError: Failed to import test module: data_steward.cdr_cleaner.cleaning_rules.ensure_date_datetime_test
Traceback (most recent call last):
  File "/usr/local/Cellar/python/3.7.7/Frameworks/Python.framework/Versions/3.7/lib/python3.7/unittest/loader.py", line 436, in _find_test_path
    module = self._get_module_from_name(name)
  File "/usr/local/Cellar/python/3.7.7/Frameworks/Python.framework/Versions/3.7/lib/python3.7/unittest/loader.py", line 377, in _get_module_from_name
    __import__(name)
  File "/Users/danyelcampbell/workspace/curation/tests/unit_tests/data_steward/cdr_cleaner/cleaning_rules/ensure_date_datetime_test.py", line 3, in <module>
    from cdr_cleaner.cleaning_rules import ensure_date_datetime_consistency as eddc
  File "/Users/danyelcampbell/workspace/curation/data_steward/cdr_cleaner/cleaning_rules/ensure_date_datetime_consistency.py", line 10, in <module>
    from cdr_cleaner.cleaning_rules import field_mapping
  File "/Users/danyelcampbell/workspace/curation/data_steward/cdr_cleaner/cleaning_rules/field_mapping.py", line 5, in <module>
    import resources
  File "/Users/danyelcampbell/workspace/curation/data_steward/resources.py", line 7, in <module>
    import cachetools
ModuleNotFoundError: No module named 'cachetools'

]]>		</error>
		<system-out>
<![CDATA[]]>		</system-out>
		<system-err>
<![CDATA[]]>		</system-err>
	</testcase>
</testsuite>
